Workbook

Sheet F-375
B2: UNIDAD DE FINANZAS DAEM
B3: LEY SEP
B4: ESCUELA: F-375 JORGE GONZALEZ BASTIAS - C.C. 2 - 2002
B5: DIRECTOR: FLOR BRAVO JARA
B6: SECTOR: | C6: NIRIVILO
B7: RBD 3489-4
B8: FECHA | C8: SOL | D8: OC | E8: DP | F8: CATEGORIA | G8: DETALLE | H8: INGRESOS | I8: GASTOS | J8: SALDO
G9: SALDO SEP 2025 | H9: ='[1]F-375'!$J$112 -> 17978.8 | J9: =+H9-I9 -> 17978.8
B10: ENERO
F11: SUBVENCION | G11: SUBVENCION | H11: =SUBVENCION!C8+SUBVENCION!D8 -> 6709442 | J11: =+J9+H11-I11 -> 6727420.8
F12: REMUNERACIONES | G12: REMUNERACIONES | I12: 5401335 | J12: =+J11+H12-I12 -> 1326085.8 | K12: ENERO | L12: INGRESOS | M12: 10% ADM | N12: RR.HH. | O12: BNS Y SERV | P12: SALDO
J13: =+J12+H13-I13 -> 1326085.8 | L13: =+H11 -> 6709442 | M13: =+L13*10% -> 670944.2 | N13: =+I12 -> 5401335 | O13: =SUM(I13:I14) -> 0 | P13: =+L13-M13-N13-O13 -> 637162.8
J14: =+J13+H14-I14 -> 1326085.8
B15: FEBRERO
F16: SUBVENCION | G16: SUBVENCION | H16: =SUBVENCION!E8+SUBVENCION!F8 -> 7112717 | J16: =J14+H16-I16 -> 8438802.8 | K16: FEBRERO | L16: INGRESOS | M16: 10% ADM | N16: RR.HH. | O16: BNS Y SERV | P16: SALDO
F17: REMUNERACIONES | G17: REMUNERACIONES | I17: 5863538 | J17: =J16+H17-I17 -> 2575264.8 | L17: =+H16 -> 7112717 | M17: =+L17*10% -> 711271.7 | N17: =+I17 -> 5863538 | O17: 0 | P17: =+L17-M17-N17-O17 -> 537907.3
B18: MARZO
F19: SUBVENCION | G19: SUBVENCION | H19: =SUBVENCION!G8+SUBVENCION!H8 -> 6843635 | J19: =J17+H19-I19 -> 9418899.8 | K19: MARZO | L19: INGRESOS | M19: 10% ADM | N19: RR.HH. | O19: BNS Y SERV | P19: SALDO
F20: REMUNERACIONES | G20: REMUNERACIONES | I20: 3700552 | J20: =J19+H20-I20 -> 5718347.8 | L20: =+H19 -> 6843635 | M20: =+L20*10% -> 684363.5 | N20: =+I20 -> 3700552 | O20: =SUM(I21:I28) -> 1982873 | P20: =+L20-M20-N20-O20 -> 475846.5
B21: 46090 | C21: 3 | D21: 74 | E21: 257 | F21: MATERIALES ENSEÑANZA | G21: LIBRERÍA | I21: 208500 | J21: =J20+H21-I21 -> 5509847.8
B22: 46090 | C22: 4 | D22: 75 | E22: 267 | F22: MATERIALES ENSEÑANZA | G22: LIBRERÍA | I22: 209649 | J22: =J21+H22-I22 -> 5300198.8
B23: 46090 | C23: 5 | D23: 76 | E23: 271 | F23: INSUMO COMPUTACIONALES | G23: TINTAS | I23: 191120 | J23: =J22+H23-I23 -> 5109078.8
B24: 46100 | C24: 6 | D24: 145 | E24: 410 | F24: MATERIALES ENSEÑANZA | G24: LIBRERÍA | I24: 209400 | J24: =J23+H24-I24 -> 4899678.8
B25: 46100 | C25: 7 | D25: 146 | E25: 382 | F25: MATERIALES ENSEÑANZA | G25: LIBRERÍA | I25: 209901 | J25: =J24+H25-I25 -> 4689777.8
B26: 46101 | C26: 8 | D26: 147 | E26: 599 | F26: COLACIONES | G26: COLACIONES | I26: 103360 | J26: =J25+H26-I26 -> 4586417.8
B27: 46111 | C27: 10 | D27: ABASTECIMIENTO | E27: NULA | F27: TRANSPORTE | G27: TRANSPORTE | J27: =J26+H27-I27 -> 4586417.8
B28: 46101 | C28: 9 | D28: 2321-145-AG26 | E28: 1035 | F28: MATERIALES ENSEÑANZA | G28: INSTRUMENTOS MUSICALES | I28: 850943 | J28: =J27+H28-I28 -> 3735474.8
B29: ABRIL
F30: SUBVENCION | G30: SUBVENCION | H30: =SUBVENCION!I8+SUBVENCION!J8 -> 6180358 | J30: =J28+H30-I30 -> 9915832.8 | K30: ABRIL | L30: INGRESOS | M30: 10% ADM | N30: RR.HH. | O30: BNS Y SERV | P30: SALDO
F31: REMUNERACIONES | G31: REMUNERACIONES | I31: 4257476 | J31: =J30+H31-I31 -> 5658356.8 | L31: =+H30 -> 6180358 | M31: =+L31*10% -> 618035.8 | N31: =+I31 -> 4257476 | O31: =SUM(I32:I35) -> 538661 | P31: =+L31-M31-N31-O31 -> 766185.2
B32: 45768 | C32: 13 | D32: 326 | E32: 744 | F32: EQUIPO DE OFICINA | G32: IMPRESORA | I32: 187000 | J32: =J31+H32-I32 -> 5471356.8
B33: 46147 | C33: 16 | D33: 389 | E33: 599 | F33: COLACIONES | G33: COLACIONES | I33: 144660 | J33: =J32+H33-I33 -> 5326696.8
B34: 46133 | C34: 14 | D34: 483 | E34: 745 | F34: MATERIALES ENSEÑANZA | G34: LIBRERÍA | I34: 207001 | J34: =J33+H34-I34 -> 5119695.8
J35: =J34+H35-I35 -> 5119695.8
J36: =J35+H36-I36 -> 5119695.8
B37: MAYO
F38: SUBVENCION | G38: SUBVENCION | H38: =SUBVENCION!K8+SUBVENCION!L8 -> 6212352 | J38: =J36+H38-I38 -> 11332048 | K38: MAYO | L38: INGRESOS | M38: 10% ADM | N38: RR.HH. | O38: BNS Y SERV | P38: SALDO
F39: REMUNERACIONES | G39: REMUNERACIONES | I39: 4243795 | J39: =J38+H39-I39 -> 7088252.8 | L39: =+H38 -> 6212352 | M39: =+L39*10% -> 621235.2 | N39: =+I39 -> 4243795 | O39: =+I40+I41+I42+I43 -> 624429 | P39: =+L39-M39-N39-O39 -> 722892.8
B40: 46156 | C40: 19 | D40: 451 | E40: 747 | F40: COLACIONES | G40: COLACIONES | I40: 178040 | J40: =J39+H40-I40 -> 6910212.8
B41: 46160 | C41: 17 | D41: 484 | F41: INSUMO COMPUTACIONALES | G41: INSUMO COMPUTACIONALES | I41: 179980 | J41: =J40+H41-I41 -> 6730232.8
...

Sheet G-389
B2: UNIDAD DE FINANZAS DAEM
B3: LEY SEP
B4: ESCUELA: G-389 ADELAIDA RIQUELME MEZA C.C.
B5: DIRECTOR: CLAUDIO SOTO BELTRAN
B6: SECTOR: LA PITIGUA
B7: RBD: 3502
B8: FECHA | C8: SOL | D8: OC | E8: DP | F8: CATEGORIA | G8: DETALLE | H8: INGRESOS | I8: GASTOS | J8: SALDO
G9: SALDO SEP 2025 | H9: ='[1]G-389'!$J$89 -> -60562.8 | J9: =+H9-I9 -> -60562.8
B10: ENERO
F11: SUBVENCION | G11: SUBVENCION | H11: =SUBVENCION!C15+SUBVENCION!D15 -> 951328 | J11: =H11-I11 -> 951328 | K11: ENERO | L11: INGRESOS | M11: 10% ADM | N11: RR.HH. | O11: BNS Y SERV | P11: SALDO
F12: REMUNERACIONES | G12: REMUNERACIONES | I12: 724618 | J12: =+J11+H12-I12 -> 226710 | L12: =+H11 -> 951328 | M12: =+L12*10% -> 95132.8 | N12: =+I12 -> 724618 | O12: 0 | P12: =+L12-M12-N12-O12 -> 131577.2
B13: FEBRERO
F14: SUBVENCION | G14: SUBVENCION | H14: =SUBVENCION!E15+SUBVENCION!F15 -> 1008141 | J14: =+J12+H14-I14 -> 1234851 | K14: FEBRERO | L14: INGRESOS | M14: 10% ADM | N14: RR.HH. | O14: BNS Y SERV | P14: SALDO
F15: REMUNERACIONES | G15: REMUNERACIONES | I15: 813283 | J15: =+J14+H15-I15 -> 421568 | L15: =+H14 -> 1008141 | M15: =+L15*10% -> 100814.1 | N15: =+I15 -> 813283 | O15: 0 | P15: =+L15-M15-N15-O15 -> 94043.9
B16: MARZO
F17: SUBVENCION | G17: SUBVENCION | H17: =SUBVENCION!G15+SUBVENCION!H15 -> 970357 | J17: =+J15+H17-I17 -> 1391925 | K17: MARZO | L17: INGRESOS | M17: 10% ADM | N17: RR.HH. | O17: BNS Y SERV | P17: SALDO
F18: REMUNERACIONES | G18: REMUNERACIONES | I18: 773497 | J18: =+J17+H18-I18 -> 618428 | L18: =+H17 -> 970357 | M18: =+L18*10% -> 97035.7 | N18: =+I18 -> 773497 | O18: =+I19+I20+I21+I22 -> 396199 | P18: =+L18-M18-N18-O18 -> -296374.7
B19: 46090 | C19: 1 | D19: 90 | E19: 421 | F19: INSUMOS COMPUTACIONES | G19: TINTAS | I19: 206600 | J19: =+J18+H19-I19 -> 411828
B20: 45727 | C20: 3 | D20: 99 | E20: 383 | F20: MATERIALES ENSEÑANZA | G20: LIBRERÍA | I20: 189599 | J20: =+J19+H20-I20 -> 222229
J21: =+J20+H21-I21 -> 222229
J22: =+J21+H22-I22 -> 222229
B23: ABRIL
F24: SUBVENCION | G24: SUBVENCION | H24: =SUBVENCION!I15+SUBVENCION!J15 -> 996498 | J24: =+J22+H24-I24 -> 1218727 | K24: ABRIL | L24: INGRESOS | M24: 10% ADM | N24: RR.HH. | O24: BNS Y SERV | P24: SALDO
F25: REMUNERACIONES | G25: REMUNERACIONES | I25: 718759 | J25: =+J24+H25-I25 -> 499968 | L25: =+H24 -> 996498 | M25: =+L25*10% -> 99649.8 | N25: =+I25 -> 718759 | O25: =I26+I27+I28+I29+I30 -> 0 | P25: =+L25-M25-N25-O25 -> 178089.2
J26: =+J25+H26-I26 -> 499968
J27: =+J26+H27-I27 -> 499968
J28: =+J27+H28-I28 -> 499968
J29: =+J28+H29-I29 -> 499968
J30: =+J29+H30-I30 -> 499968
B31: MAYO
F32: SUBVENCION | G32: SUBVENCION | H32: =SUBVENCION!K15+SUBVENCION!L15 -> 977415 | J32: =+J30+H32-I32 -> 1477383 | K32: MAYO | L32: INGRESOS | M32: 10% ADM | N32: RR.HH. | O32: BNS Y SERV | P32: SALDO
F33: REMUNERACIONES | G33: REMUNERACIONES | I33: 361693 | J33: =+J32+H33-I33 -> 1115690 | L33: =+H32 -> 977415 | M33: =+L33*10% -> 97741.5 | N33: =+I33 -> 361693 | O33: =+I34+I35+I36+I37 -> 412291 | P33: =+L33-M33-N33-O33 -> 105689.5
B34: 46169 | C34: 15 | D34: 503 | E34: 845 | F34: VESTUARIO | G34: BUZOS | I34: 201001 | J34: =+J33+H34-I34 -> 914689
B35: 46169 | C35: 17 | D35: 502 | E35: 843 | F35: MATERIAL ENSEÑANZA | G35: MANUALIDADES ARTES | I35: =127350+83940 -> 211290 | J35: =+J34+H35-I35 -> 703399
J36: =+J35+H36-I36 -> 703399
J37: =+J36+H37-I37 -> 703399
J38: =+J37+H38-I38 -> 703399
B39: JUNIO
F40: SUBVENCION | G40: SUBVENCION | H40: =SUBVENCION!M15+SUBVENCION!N15 -> 963081 | J40: =+J38+H40-I40 -> 1666480 | K40: JUNIO | L40: INGRESOS | M40: 10% ADM | N40: RR.HH. | O40: BNS Y SERV | P40: SALDO
F41: REMUNERACIONES | G41: REMUNERACIONES | I41: 368769 | J41: =+J40+H41-I41 -> 1297711 | L41: =+H40 -> 963081 | M41: =+L41*10% -> 96308.1 | N41: =+I41 -> 368769 | O41: =I42+I43+I44 -> 0 | P41: =+L41-M41-N41-O41 -> 498003.9
...

Sheet G-394
B2: UNIDAD DE FINANZAS DAEM
B3: LEY SEP
B4: ESCUELA: G-394 INES DE SUAREZ
B5: DIRECTOR: JULIO MUÑOZ
B6: SECTOR: RASTROJOS
B7: RBD: 3506
B8: FECHA | C8: SOL | D8: OC | E8: DP | F8: CATEGORIA | G8: DETALLE | H8: INGRESOS | I8: GASTOS | J8: SALDO
G9: SALDO SEP 2025 | H9: ='[1]G-394'!$J$105 -> -365551.5 | J9: =+H9-I9 -> -365551.5
B10: ENERO
F11: SUBVENCION | G11: SUBVENCION | H11: =SUBVENCION!C16+SUBVENCION!D16 -> 990720 | J11: =H11-I11 -> 990720 | K11: ENERO | L11: INGRESOS | M11: 10% ADM | N11: RR.HH. | O11: BNS Y SERV | P11: SALDO
F12: REMUNERACIONES | G12: REMUNERACIONES | I12: 159835 | J12: =+J11+H12-I12 -> 830885 | L12: =+H11 -> 990720 | M12: =+L12*10% -> 99072 | N12: =+I12 -> 159835 | O12: 0 | P12: =+L12-M12-N12-O12 -> 731813
B13: FEBRERO
F14: SUBVENCION | G14: SUBVENCION | H14: =SUBVENCION!E16+SUBVENCION!F16 -> 1051150 | J14: =+J12+H14-I14 -> 1882035 | K14: FEBRERO | L14: INGRESOS | M14: 10% ADM | N14: RR.HH. | O14: BNS Y SERV | P14: SALDO
F15: REMUNERACIONES | G15: REMUNERACIONES | I15: 163044 | J15: =+J14+H15-I15 -> 1718991 | L15: =+H14 -> 1051150 | M15: =+L15*10% -> 105115 | N15: =+I15 -> 163044 | O15: 0 | P15: =+L15-M15-N15-O15 -> 782991
B16: MARZO
F17: SUBVENCION | G17: SUBVENCION | H17: =SUBVENCION!G15+SUBVENCION!H15 -> 970357 | J17: =+J15+H17-I17 -> 2689348 | K17: MARZO | L17: INGRESOS | M17: 10% ADM | N17: RR.HH. | O17: BNS Y SERV | P17: SALDO
F18: REMUNERACIONES | G18: REMUNERACIONES | I18: 19021 | J18: =+J17+H18-I18 -> 2670327 | L18: =+H17 -> 970357 | M18: =+L18*10% -> 97035.7 | N18: =+I18 -> 19021 | O18: =I19+I20+I21+I22+I23+I24+I25+I26 -> 594018 | P18: =+L18-M18-N18-O18 -> 260282.3
B19: 46099 | C19: 3 | D19: 131 | E19: 379 | F19: MATERIALES ENSEÑANZA | G19: LIBRERÍA | I19: 205279 | J19: =+J18+H19-I19 -> 2465048
B20: 46100 | C20: 4 | D20: 144 | E20: 379 | F20: INSUMO COMPUTACIONES | G20: TINTAS | I20: 207839 | J20: =+J19+H20-I20 -> 2257209
B21: 46104 | C21: 5 | D21: 156 | E21: 411 | F21: EQUIPO DE OFICINA | G21: IMPRESORA | I21: 180900 | J21: =+J20+H21-I21 -> 2076309
J22: =+J21+H22-I22 -> 2076309
J23: =+J22+H23-I23 -> 2076309
J24: =+J23+H24-I24 -> 2076309
J25: =+J24+H25-I25 -> 2076309
J26: =+J25+H26-I26 -> 2076309
B27: ABRIL
F28: SUBVENCION | G28: SUBVENCION | H28: =SUBVENCION!I16+SUBVENCION!J16 -> 996191 | J28: =+J26+H28-I28 -> 3072500 | K28: ABRIL | L28: INGRESOS | M28: 10% ADM | N28: RR.HH. | O28: BNS Y SERV | P28: SALDO
F29: REMUNERACIONES | G29: REMUNERACIONES | I29: 81664 | J29: =+J28+H29-I29 -> 2990836 | L29: =+H28 -> 996191 | M29: =+L29*10% -> 99619.1 | N29: =+I29 -> 81664 | O29: =+I30+I31+I32+I33+I34+I35+I36+I37 -> 1568871 | P29: =+L29-M29-N29-O29 -> -753963.1
B30: 46118 | C30: 6 | D30: 254 | E30: 575 | F30: MATERIALES ENSEÑANZA | G30: LIBRERÍA | I30: 206630 | J30: =+J29+H30-I30 -> 2784206
B31: 46120 | C31: 8 | D31: 255 | E31: 606 | F31: MATERIALES ENSEÑANZA | G31: INSTRUMENTO MUSICALES | I31: 199000 | J31: =+J30+H31-I31 -> 2585206
B32: 46132 | C32: 9 | D32: 331 | E32: 568 | F32: VESTUARIO | G32: TRAJE FLOLCLORICO TALLER | I32: 202895 | J32: =+J31+H32-I32 -> 2382311
B33: 46136 | C33: 15 | D33: 341 | E33: 644 | F33: VESTUARIO | G33: BUZO DEPORTIVO TALLER | I33: 201000 | J33: =+J32+H33-I33 -> 2181311
B34: 46136 | C34: 16 | D34: 342 | E34: 703 | F34: COLACIONES | G34: COLACIONES | I34: 150000 | J34: =+J33+H34-I34 -> 2031311
B35: 46135 | C35: 13 | D35: 340 | E35: 750 | F35: MATERIALES ENSEÑANZA | G35: IMPLEMENTOS DEPORTIVO TALLER | I35: 205632 | J35: =+J34+H35-I35 -> 1825679
B36: 46140 | C36: 21 | D36: 364 | E36: 706 | F36: MOBILIARIO | G36: ESTUFA | I36: 209000 | J36: =+J35+H36-I36 -> 1616679
B37: 46136 | C37: 18 | D37: 359 | E37: 755 | F37: MOBILIARIA | G37: PARLANTE | I37: 194714 | J37: =+J36+H37-I37 -> 1421965
B38: MAYO
F39: SUBVENCION | G39: SUBVENCION | H39: =SUBVENCION!K16+SUBVENCION!L16 -> 963203 | J39: =+J37+H39-I39 -> 2385168 | K39: MAYO | L39: INGRESOS | M39: 10% ADM | N39: RR.HH. | O39: BNS Y SERV | P39: SALDO
F40: REMUNERACIONES | G40: REMUNERACIONES | I40: 84576 | J40: =+J39+H40-I40 -> 2300592 | L40: =+H39 -> 963203 | M40: =+L40*10% -> 96320.3 | N40: =+I40 -> 84576 | O40: =I41+I42+I43+I44 -> 808385 | P40: =+L40-M40-N40-O40 -> -26078.3
B41: 46148 | C41: 22 | D41: 393 | E41: 747 | F41: COLACIONES | G41: COLACIONES | I41: 209300 | J41: =+J40+H41-I41 -> 2091292
...

Sheet E-403
B3: LEY SEP
B4: ESCUELA: E-403 MANUEL BALMACEDA C.C. 2014
B5: DIRECTOR: RICARDO BRAVO
B6: SECTOR: SAN JAVIER
B7: RBD: 3480
B8: FECHA | C8: SOL | D8: OC | E8: DP | F8: CATEGORIA | G8: DETALLE | H8: INGRESOS | I8: GASTOS | J8: SALDO
G9: SALDO SEP 2025 | H9: ='[1]E-403'!$J$169 -> -2782179.7 | J9: =+H9-I9 -> -2782179.7
B10: ENERO
F11: SUBVENCION | G11: SUBVENCION | H11: =SUBVENCION!C4+SUBVENCION!D4 -> 38510402 | J11: =H11-I11 -> 38510402 | K11: ENERO | L11: INGRESOS | M11: 10% ADM | N11: RR.HH. | O11: BNS Y SERV | P11: SALDO
F12: REMUNERACIONES | G12: REMUNERACIONES | I12: 26268456 | J12: =+J11+H12-I12 -> 12241946 | L12: =+H11 -> 38510402 | M12: =+L12*10% -> 3851040.2 | N12: =+I12 -> 26268456 | O12: =I13+I14+I15+I16+I17 -> 11718988 | P12: =+L12-M12-N12-O12 -> -3328082.2
F13: ARRIENDO | G13: ARRIENDO TALLERES DICIEMBRE | I13: 4514400 | J13: =+J12+H13-I13 -> 7727546
B14: 46045 | C14: 1 | D14: 2321-56-AG26 | E14: 403 | F14: INSUMO COMPUTACIONALES | G14: TONER | I14: 1976019 | J14: =+J13+H14-I14 -> 5751527
E15: 55 | F15: INTERNET | G15: INTERNET | I15: 82557 | J15: =+J14+H15-I15 -> 5668970
E16: 55 | F16: INTERNET | G16: INTERNET | I16: 631612 | J16: =+J15+H16-I16 -> 5037358
E17: 13 | F17: ARRIENDO | G17: ARRIENDO TALLERES DICIEMBRE | I17: 4514400 | J17: =+J16+H17-I17 -> 522958
B18: FEBRERO
F19: SUBVENCION | G19: SUBVENCION | H19: =SUBVENCION!E4+SUBVENCION!F4 -> 40811856 | J19: =+J17+H19-I19 -> 41334814 | K19: FEBRERO | L19: INGRESOS | M19: 10% ADM | N19: RR.HH. | O19: BNS Y SERV | P19: SALDO
F20: REMUNERACIONES | G20: REMUNERACIONES | I20: 28099384 | J20: =+J19+H20-I20 -> 13235430 | L20: =+H19 -> 40811856 | M20: =+L20*10% -> 4081185.6 | N20: =+I20 -> 28099384 | O20: =+I22+I21 -> 713963 | P20: =+L20-M20-N20-O20 -> 7917323.4
E21: 161 | F21: INTERNET | G21: INTERNET | I21: 82741 | J21: =+J20+H21-I21 -> 13152689
E22: 161 | F22: INTERNET | G22: INTERNET | I22: 631222 | J22: =+J21+H22-I22 -> 12521467
B23: MARZO
F24: SUBVENCION | G24: SUBVENCION | H24: =SUBVENCION!G4+SUBVENCION!H4 -> 39280618 | J24: =+J22-I24+H24 -> 51802085 | K24: MARZO | L24: INGRESOS | M24: 10% ADM | N24: RR.HH. | O24: BNS Y SERV | P24: SALDO
F25: REMUNERACIONES | G25: REMUNERACIONES | I25: 22614496 | J25: =+J24+H25-I25 -> 29187589 | L25: =+H24 -> 39280618 | M25: =+L25*10% -> 3928061.8 | N25: =+I25 -> 22614496 | O25: =I26+I27+I28+I29+I30+I31+I32+I33+I34+I35+I36 -> 7367194 | P25: =+L25-M25-N25-O25 -> 5370866.2
E26: 375 | F26: ARRIENDO | G26: ARRIENDO TALLERES MARZO | I26: 4672404 | J26: =+J25+H26-I26 -> 24515185
B27: 46085 | C27: 3 | D27: 34 | E27: 382 | F27: MATERIALES OFICINA | G27: LIBRERÍA | I27: 208461 | J27: =+J26+H27-I27 -> 24306724
B28: 46091 | C28: 5 | D28: 100 | E28: 389 | F28: MATERIALES ENSEÑANZA | G28: LIBRERÍA | I28: 206510 | J28: =+J27+H28-I28 -> 24100214
E29: 223 | F29: INTERNET | G29: INTERNET | I29: 82210 | J29: =+J28+H29-I29 -> 24018004
E30: 293 | F30: INTERNET | G30: INTERNET | I30: 632698 | J30: =+J29+H30-I30 -> 23385306
B31: 45735 | C31: 9 | D31: 150 | E31: 379 | F31: MATERIALES ENSEÑANZA | G31: MATERIALES ENSEÑANZA | I31: 205930 | J31: =J30+H31-I31 -> 23179376
B32: 46100 | C32: 10 | D32: 151 | E32: 462 | F32: COLACIONES | G32: TORTA | I32: 155600 | J32: =J31+H32-I32 -> 23023776
B33: 45734 | C33: 6 | D33: 149 | E33: 390 | F33: INSUMO COMPUTACIONALES | G33: TINTAS | I33: 194850 | J33: =J32+H33-I33 -> 22828926
B34: 46108 | C34: 13 | D34: 203 | E34: 407 | F34: EQUIPO OFICINA | G34: IMPRESORA | I34: 189990 | J34: =J33+H34-I34 -> 22638936
B35: 46108 | C35: 15 | D35: 204 | E35: 429 | F35: MATERIALES ENSEÑANZA | G35: LIBRERÍA | I35: 208981 | J35: =J34+H35-I35 -> 22429955
B36: 46093 | C36: 12 | D36: 2321-109-AG26 | E36: 646 | F36: MATERIAL DE ENSEÑANZA | G36: JUEGO PEDAGOGICOS | I36: 609560 | J36: =J35+H36-I36 -> 21820395
B37: ABRIL
F38: SUBVENCION | G38: SUBVENCION | H38: =SUBVENCION!I4+SUBVENCION!J4 -> 35290486 | J38: =+J36+H38-I38 -> 57110881 | K38: ABRIL | L38: INGRESOS | M38: 10% ADM | N38: RR.HH. | O38: BNS Y SERV | P38: SALDO
F39: REMUNERACIONES | G39: REMUNERACIONES | I39: 24923503 | J39: =+J38+H39-I39 -> 32187378 | L39: =+H38 -> 35290486 | M39: =+L39*10% -> 3529048.6 | N39: =+I39 -> 24923503 | O39: =I40+I41+I42+I43+I44+I45+I46+I47 -> 14108069 | P39: =+L39-M39-N39-O39 -> -7270134.6
E40: 351 | F40: INTERNET | G40: INTERNET | I40: 82403 | J40: =+J39+H40-I40 -> 32104975
E41: 455 | F41: INTERNET | G41: INTERNET | I41: 633419 | J41: =+J40+H41-I41 -> 31471556
E42: 573 | F42: ARRIENDO | G42: ARRIENDO TALLERES ABRIL | I42: 4672404 | J42: =+J41+H42-I42 -> 26799152
...

Sheet F-405
B2: UNIDAD DE FINANZAS DAEM
B3: LEY SEP
B4: ESCUELA: F-405 JULIO MONTT SALAMANCA
B5: DIRECTOR: JACQUELINE GUZMAN
B6: SECTOR:
B7: REBD: 3490
B8: FECHA | C8: SOL | D8: OC | E8: DP | F8: CATEGORIA | G8: DETALLE | H8: INGRESOS | I8: GASTOS | J8: SALDO
G9: SALDO 2025 | H9: ='[1]F-405'!$J$125 -> 1076784.2 | J9: =+H9-I9 -> 1076784.2
B10: ENERO
F11: SUBVENCION | G11: SUBVENCION | H11: =SUBVENCION!C9+SUBVENCION!D9 -> 12694999 | J11: =J9+H11-I11 -> 13771783 | K11: ENERO | L11: INGRESOS | M11: 10% ADM | N11: RR.HH. | O11: BNS Y SERV | P11: SALDO
F12: REMUNERACIONES | G12: REMUNERACIONES | I12: 7861759 | J12: =+J11+H12-I12 -> 5910024.2 | L12: =+H11 -> 12694999 | M12: =+L12*10% -> 1269499.9 | N12: =+I12 -> 7861759 | O12: =I13 -> 38773 | P12: =+L12-M12-N12-O12 -> 3524967.1
E13: 12 | F13: INTERNET | G13: INTERNET | I13: 38773 | J13: =+J12+H13-I13 -> 5871251.2
B14: FEBRERO
F15: SUBVENCION | G15: SUBVENCION | H15: =SUBVENCION!E9+SUBVENCION!F9 -> 13454884 | J15: =+J13+H15-I15 -> 19326135 | K15: FEBRERO | L15: INGRESOS | M15: 10% ADM | N15: RR.HH. | O15: BNS Y SERV | P15: SALDO
F16: REMUNERACIONES | G16: REMUNERACIONES | I16: 8511945 | J16: =+J15+H16-I16 -> 10814190 | L16: =H15 -> 13454884 | M16: =+L16*10% -> 1345488.4 | N16: =+I16 -> 8511945 | O16: =+I17+I18 -> 247576 | P16: =+L16-M16-N16-O16 -> 3349874.6
B17: 46079 | C17: 1 | D17: 14 | E17: 634 | F17: INSUMOS COMPUTACIONALES | G17: TINTAS | I17: 208803 | J17: =+J16+H17-I17 -> 10605387
E18: 130 | F18: INTERNET | G18: INTERNET | I18: 38773 | J18: =+J17+H18-I18 -> 10566614
B19: MARZO
F20: SUBVENCION | G20: SUBVENCION | H20: =SUBVENCION!G9+SUBVENCION!H9 -> 12948901 | J20: =+J18+H20-I20 -> 23515515 | K20: MARZO
F21: REMUNERACIONES | G21: REMUNERACIONES | I21: 9306097 | J21: =+J20+H21-I21 -> 14209418
B22: 46084 | C22: 3 | D22: 22 | E22: 263 | F22: MATERIALES OFICINA | G22: LIBRERÍA | I22: 205302 | J22: =+J21+H22-I22 -> 14004116 | L22: INGRESOS | M22: 10% ADM | N22: RR.HH. | O22: BNS Y SERV | P22: SALDO
B23: 46085 | C23: 4 | D23: 35 | E23: 257 | F23: MATERIALES OFICINA | G23: LIBRERÍA | I23: 208900 | J23: =+J22+H23-I23 -> 13795216 | L23: =H20 -> 12948901 | M23: =+L23*10% -> 1294890.1 | N23: =I21 -> 9306097 | O23: =I22+I23+I24+I25+I26+I27 -> 1238624 | P23: =+L23-M23-N23-O23 -> 1109289.9
E24: 222 | F24: INTERNET | G24: INTERNET | I24: 38773 | J24: =+J23+H24-I24 -> 13756443
B25: 46104 | C25: 7 | D25: 157 | E25: 427 | F25: INSUMO COMPUTACIONALES | G25: INSUMO COMPUTACIONALES | I25: 197920 | J25: =+J24+H25-I25 -> 13558523
B26: 46112 | C26: 11 | D26: 206 | E26: 599 | F26: COLACIONES | G26: COLACIONES | I26: 208010 | J26: =+J25+H26-I26 -> 13350513
B27: 46105 | C27: 9 | D27: 2123-97-AG26 | E27: 613 | F27: MATERIALES OFICINA | G27: RESMAS | I27: 379719 | J27: =+J26+H27-I27 -> 12970794
J28: =+J27+H28-I28 -> 12970794
J29: =+J28+H29-I29 -> 12970794
J30: =+J29+H30-I30 -> 12970794
J31: =+J30+H31-I31 -> 12970794
J32: =+J31+H32-I32 -> 12970794
J33: =+J32+H33-I33 -> 12970794
B34: ABRIL
F35: SUBVENCION | G35: SUBVENCION | H35: =SUBVENCION!I9+SUBVENCION!J9 -> 11863643 | J35: =+J33+H35-I35 -> 24834437 | K35: ABRIL
F36: REMUNERACIONES | G36: REMUNERACIONES | I36: 8802976 | J36: =+J35+H36-I36 -> 16031461 | L36: INGRESOS | M36: 10% ADM | N36: RR.HH. | O36: BNS Y SERV | P36: SALDO
E37: 350 | F37: INTERNET | G37: INTERNET | I37: 38773 | J37: =+J36+H37-I37 -> 15992688 | L37: =H35 -> 11863643 | M37: =+L37*10% -> 1186364.3 | N37: =I36 -> 8802976 | O37: =I37+I38+I39+I40+I41+I42+I43+I44+I45+I46+I47 -> 1073149 | P37: =+L37-M37-N37-O37 -> 801153.7
B38: 45749 | C38: 12 | D38: 217 | E38: 419 | F38: PREMIOS | G38: PREMIOS | I38: 208506 | J38: =+J37+H38-I38 -> 15784182
B39: 45753 | C39: 13 | D39: 231 | E39: 574 | F39: INSUMO COMPUTACIONALES | G39: TONER | I39: 207969 | J39: =+J38+H39-I39 -> 15576213
B40: 46119 | C40: 14 | D40: 251 | E40: 653 | F40: MATERIALES DE ENSEÑANZA | G40: BALONES TALLER DEPORTIVO | I40: 206902 | J40: =+J39+H40-I40 -> 15369311
B41: 46128 | C41: 19 | D41: 294 | E41: 651 | F41: INSUMO COMPUTACIONALES | G41: INSUMO COMPUTACIONALES | I41: 203999 | J41: =+J40+H41-I41 -> 15165312
...

Sheet F-407
B2: UNIDAD DE FINANZAS DAEM
B3: LEY SEP
B4: ESCUELA: F-407 JUAN DE DIOS ALDEA
B5: DIRECTOR: MATIAS VALENZUELA
B6: SECTOR:
B7: RBD: 3491
B8: FECHA | C8: SOL | D8: OC | E8: DP | F8: CATEGORIA | G8: DETALLE | H8: INGRESOS | I8: GASTOS | J8: SALDO
G9: SALDO 2025 | H9: 2559585 | J9: =+H9-I9 -> 2559585
B10: ENERO
F11: SUBVENCION | G11: SUBVENCION | H11: =SUBVENCION!C10+SUBVENCION!D10 -> 7160173 | J11: =+H11 -> 7160173 | K11: ENERO | L11: INGRESOS | M11: 10% ADM | N11: RR.HH. | O11: BNS Y SERV | P11: SALDO
F12: REMUNERACIONES | G12: REMUNERACIONES | I12: 4323530 | J12: =+J11+H12-I12 -> 2836643 | L12: =+H11 -> 7160173 | M12: =+L12*10% -> 716017.3 | N12: =+I12 -> 4323530 | O12: =I13 -> 0 | P12: =+L12-M12-N12-O12 -> 2120625.7
J13: =+J12+H13-I13 -> 2836643
B14: FEBRERO
F15: SUBVENCION | G15: SUBVENCION | H15: =SUBVENCION!E10+SUBVENCION!F10 -> 7593265 | J15: =+J13+H15-I15 -> 10429908 | K15: FEBRERO | L15: INGRESOS | M15: 10% ADM | N15: RR.HH. | O15: BNS Y SERV | P15: SALDO
F16: REMUNERACIONES | G16: REMUNERACIONES | I16: 4653014 | J16: =+J15+H16-I16 -> 5776894 | L16: =+H15 -> 7593265 | M16: =+L16*10% -> 759326.5 | N16: =+I16 -> 4653014 | O16: =I17 -> 0 | P16: =+L16-M16-N16-O16 -> 2180924.5
J17: =+J16+H17-I17 -> 5776894
B18: MARZO
F19: SUBVENCION | G19: SUBVENCION | H19: =SUBVENCION!G10+SUBVENCION!H10 -> 7303374 | J19: =+J17+H19-I19 -> 13080268 | K19: MARZO | L19: INGRESOS | M19: 10% ADM | N19: RR.HH. | O19: BNS Y SERV | P19: SALDO
F20: REMUNERACIONES | G20: REMUNERACIONES | I20: 4690763 | J20: =+J19+H20-I20 -> 8389505 | L20: =+H19 -> 7303374 | M20: =+L20*10% -> 730337.4 | N20: =+I20 -> 4690763 | O20: =I21+I22+I23+I24+I25+I26+I27 -> 1510108 | P20: =+L20-M20-N20-O20 -> 372165.6
B21: 46083 | C21: 3 | D21: 24 | E21: 265 | F21: MATERIALES OFICINA | G21: LIBRERÍA | I21: 159030 | J21: =+J20+H21-I21 -> 8230475
B22: 46083 | C22: 1 | D22: 23 | E22: 265 | F22: MATERIALES ENSEÑANZA | G22: LIBROS | I22: 159030 | J22: =+J21+H22-I22 -> 8071445
B23: 46084 | C23: 2 | D23: 33 | E23: 265 | F23: MATERIALES ENSEÑANZA | G23: LIBROS TRAZOS Y LETRAS | I23: 155850 | J23: =+J22+H23-I23 -> 7915595
B24: 46087 | C24: 6 | D24: 54 | E24: 266 | F24: MATERIALES ENSEÑANZA | G24: LIBRERÍA | I24: 207010 | J24: =+J23+H24-I24 -> 7708585
B25: 46090 | C25: 7 | D25: 62 | E25: 261 | F25: CONSUMO | G25: CONSUMO | I25: 209000 | J25: =+J24+H25-I25 -> 7499585
B26: 46085 | C26: 4 | D26: 2321-55-AG26 | E26: 405 | F26: INSUMO COMPUTACIONALES | G26: TONER | I26: 415548 | J26: =+J25+H26-I26 -> 7084037
B27: 46098 | C27: 9 | D27: 130 | E27: 389 | F27: MATERIALES ENSEÑANZA | G27: LIBRERÍA | I27: 204640 | J27: =+J26+H27-I27 -> 6879397
J28: =+J27+H28-I28 -> 6879397
B29: ABRIL
F30: SUBVENCION | G30: SUBVENCION | H30: =SUBVENCION!I10+SUBVENCION!J10 -> 7031783 | J30: =+J28+H30-I30 -> 13911180 | K30: ABRIL | L30: INGRESOS | M30: 10% ADM | N30: RR.HH. | O30: BNS Y SERV | P30: SALDO
F31: REMUNERACIONES | G31: REMUNERACIONES | I31: 4902671 | J31: =+J30+H31-I31 -> 9008509 | L31: =+H30 -> 7031783 | M31: =+L31*10% -> 703178.3 | N31: =+I31 -> 4902671 | O31: =I32+I33+I34+I35+I36 -> 1873912 | P31: =+L31-M31-N31-O31 -> -447978.3
B32: 46114 | C32: 15 | D32: 214 | E32: 575 | F32: MATERILAES ENSEÑANZA | G32: RESMA | I32: 204590 | J32: =+J31+H32-I32 -> 8803919
B33: 46121 | C33: 16 | D33: 2123-117-AG26 | E33: 770 | F33: MATERILAES ENSEÑANZA | G33: LIBRERÍA | I33: 682843 | J33: =+J32+H33-I33 -> 8121076
B34: 46133 | C34: 17 | D34: 2321-129-AG26 | E34: 773 | F34: INSUMO COMPUTACIONALES | G34: TONER | I34: 380800 | J34: =+J33+H34-I34 -> 7740276
B35: 46139 | C35: 18 | D35: 2321-169-AG26 | E35: 1069 | F35: INSUMO COMPUTACIONALES | G35: MICROFONO -PARLANTES | I35: 605679 | J35: =+J34+H35-I35 -> 7134597
J36: =+J35+H36-I36 -> 7134597
B37: MAYO
F38: SUBVENCION | G38: SUBVENCION | H38: =SUBVENCION!K10+SUBVENCION!L10 -> 7033366 | J38: =+J36+H38-I38 -> 14167963 | K38: MAYO | L38: INGRESOS | M38: 10% ADM | N38: RR.HH. | O38: BNS Y SERV | P38: SALDO
F39: REMUNERACIONES | G39: REMUNERACIONES | I39: 4899288 | J39: =+J38+H39-I39 -> 9268675 | L39: =+H38 -> 7033366 | M39: =+L39*10% -> 703336.6 | N39: =+I39 -> 4899288 | O39: =I40+I41+I42 -> 496830 | P39: =+L39-M39-N39-O39 -> 933911.4
B40: 46149 | C40: 20 | D40: 400 | E40: 756 | F40: TRASLADO | G40: TRANSPORTE | I40: 80000 | J40: =+J39+H40-I40 -> 9188675
B41: 46153 | C41: 21 | D41: 433 | E41: 808 | F41: COLACIONES | G41: COLACIONES | I41: 210000 | J41: =+J40+H41-I41 -> 8978675
...

Sheet G-412
B2: UNIDAD DE FINANZAS DAEM
B3: LEY SEP
B4: ESCUELA: G-412 RAMON CARNICER
B5: DIRECTOR: GABRIEL JAQUE MARIN
B6: SECTOR:
B7: RBD: 3515
B8: FECHA | C8: SOL | D8: OC | E8: DP | F8: CATEGORIA | G8: DETALLE | H8: INGRESOS | I8: GASTOS | J8: SALDO
G9: SALDO 2025 | H9: ='[1]G-412'!$J$94 -> 516412.6 | J9: =+H9-I9 -> 516412.6
B10: ENERO
F11: SUBVENCION | G11: SUBVENCION | H11: =SUBVENCION!C17+SUBVENCION!D17 -> 3279538 | J11: =J9+H11-I11 -> 3795950.6 | K11: ENERO | L11: INGRESOS | M11: 10% ADM | N11: RR.HH. | O11: BNS Y SERV | P11: SALDO
F12: REMUNERACIONES | G12: REMUNERACIONES | I12: 2514764 | J12: =+J11+H12-I12 -> 1281186.6 | L12: =+H11 -> 3279538 | M12: =+L12*10% -> 327953.8 | N12: =+I12 -> 2514764 | O12: 0 | P12: =+L12-M12-N12-O12 -> 436820.2
B13: FEBRERO
F14: SUBVENCION | G14: SUBVENCION | H14: =SUBVENCION!E17+SUBVENCION!F17 -> 3478421 | J14: =+J12+H14-I14 -> 4759607.6 | K14: FEBRERO | L14: INGRESOS | M14: 10% ADM | N14: RR.HH. | O14: BNS Y SERV | P14: SALDO
F15: REMUNERACIONES | G15: REMUNERACIONES | I15: 3755289 | J15: =+J14+H15-I15 -> 1004318.6 | L15: =+H14 -> 3478421 | M15: =+L15*10% -> 347842.1 | N15: =+I15 -> 3755289 | O15: 0 | P15: =+L15-M15-N15-O15 -> -624710.1
B16: MARZO
F17: SUBVENCION | G17: SUBVENCION | H17: =SUBVENCION!G17+SUBVENCION!H17 -> 3345129 | J17: =+J15+H17-I17 -> 4349447.6 | K17: MARZO | L17: INGRESOS | M17: 10% ADM | N17: RR.HH. | O17: BNS Y SERV | P17: SALDO
F18: REMUNERACIONES | G18: REMUNERACIONES | I18: 2584197 | J18: =+J17+H18-I18 -> 1765250.6 | L18: =+H17 -> 3345129 | M18: =+L18*10% -> 334512.9 | N18: =+I18 -> 2584197 | O18: =I19++I20+I21+I22+I23+I24+I25+I26+I27 -> 824974 | P18: =+L18-M18-N18-O18 -> -398554.9
B19: 46086 | C19: 2 | D19: 51 | E19: 270 | F19: INSUMO COMPUTACIONALES | G19: TONER | I19: 208250 | J19: =+J18+H19-I19 -> 1557000.6
B20: 46092 | C20: 4 | D20: 84 | E20: 398 | F20: MATERIALES ENSEÑANZA | G20: MATERIALES | I20: 204894 | J20: =+J19+H20-I20 -> 1352106.6
B21: 46093 | C21: 6 | D21: 104 | E21: 379 | F21: MATERIALES ENSEÑANZA | G21: LIBRERÍA | I21: 202830 | J21: =+J20+H21-I21 -> 1149276.6
B22: 46098 | C22: 8 | D22: 124 | E22: 382 | F22: MATERIALES ENSEÑANZA | G22: LIBRERÍA | I22: 209000 | J22: =+J21+H22-I22 -> 940276.6
J23: =+J22+H23-I23 -> 940276.6
J24: =+J23+H24-I24 -> 940276.6
J25: =+J24+H25-I25 -> 940276.6
J26: =+J25+H26-I26 -> 940276.6
J27: =+J26+H27-I27 -> 940276.6
B28: ABRIL
F29: SUBVENCION | G29: SUBVENCION | H29: =SUBVENCION!I17+SUBVENCION!J17 -> 3654868 | J29: =+J27+H29-I29 -> 4595144.6 | K29: ABRIL | L29: INGRESOS | M29: 10% ADM | N29: RR.HH. | O29: BNS Y SERV | P29: SALDO
F30: REMUNERACIONES | G30: REMUNERACIONES | I30: 2526058 | J30: =+J29+H30-I30 -> 2069086.6 | L30: =+H29 -> 3654868 | M30: =+L30*10% -> 365486.8 | N30: =+I30 -> 2526058 | O30: =I31+I32+I33+I34+I35+I36 -> 149420 | P30: =+L30-M30-N30-O30 -> 613903.2
B31: 46133 | C31: 10 | D31: 327 | E31: 745 | F31: MATERIALES ENSEÑANZA | G31: LIBRERÍA | I31: 149420 | J31: =+J30+H31-I31 -> 1919666.6
J32: =+J31+H32-I32 -> 1919666.6
J33: =+J32+H33-I33 -> 1919666.6
J34: =+J33+H34-I34 -> 1919666.6
J35: =+J34+H35-I35 -> 1919666.6
J36: =+J35+H36-I36 -> 1919666.6
B37: MAYO
F38: SUBVENCION | G38: SUBVENCION | H38: =SUBVENCION!K17+SUBVENCION!L17 -> 3665311 | J38: =+J36+H38-I38 -> 5584977.6 | K38: MAYO | L38: INGRESOS | M38: 10% ADM | N38: RR.HH. | O38: BNS Y SERV | P38: SALDO
F39: REMUNERACIONES | G39: REMUNERACIONES | I39: 2552862 | J39: =+J38+H39-I39 -> 3032115.6 | L39: =+H38 -> 3665311 | M39: =+L39*10% -> 366531.1 | N39: =+I39 -> 2552862 | O39: =I40 -> 211130 | P39: =+L39-M39-N39-O39 -> 534787.9
B40: 46162 | C40: 13 | D40: 467 | E40: 746 | F40: MATERIALES OFICINA | G40: LIBRERÍA | I40: 211130 | J40: =+J39+H40-I40 -> 2820985.6
B41: 46162 | C41: 12 | D41: 468 | E41: NULA | F41: MOBILIARIO Y OTROS | G41: MOBILIARIO Y OTROS | I41: 0 | J41: =+J40+H41-I41 -> 2820985.6
...

Sheet F-413
B2: UNIDAD DE FINANZAS DAEM
B3: LEY SEP
B4: Escuela: F-413 BERNARDO O´HIGGINS - RBD 3492
B5: Director: STEFANIE FAUNDEZ
B6: SECTOR:
B7: RBD: 3492
B8: FECHA | C8: SOL | D8: OC | E8: DP | F8: CATEGORIA | G8: DETALLE | H8: INGRESOS | I8: GASTOS | J8: SALDO
G9: SALDO 2025 | H9: ='[1]F-413'!$J$127 -> 1010389.5 | J9: =+H9-I9 -> 1010389.5
B10: ENERO
F11: SUBVENCION | G11: SUBVENCION | H11: =SUBVENCION!C11+SUBVENCION!D11 -> 11263770 | J11: =+J9+H11-I11 -> 12274160 | L11: ENERO | M11: INGRESOS | N11: 10% ADM | O11: RR.HH. | P11: BNS Y SERV | Q11: SALDO
F12: REMUNERACIONES | G12: REMUNERACIONES | I12: 9558021 | J12: =J11+H12-I12 -> 2716138.5 | M12: =+H11 -> 11263770 | N12: =+M12*10% -> 1126377 | O12: =+I12 -> 9558021 | P12: 0 | Q12: =+M12-N12-O12-P12 -> 579372
B13: FEBRERO
F14: SUBVENCION | G14: SUBVENCION | H14: =SUBVENCION!E11+SUBVENCION!F11 -> 11947720 | J14: =+J12+H14-I14 -> 14663858 | L14: FEBRERO | M14: INGRESOS | N14: 10% ADM | O14: RR.HH. | P14: BNS Y SERV | Q14: SALDO
F15: REMUNERACIONES | G15: REMUNERACIONES | I15: 10220190 | J15: =+J14+H15-I15 -> 4443668.5 | M15: =+H14 -> 11947720 | N15: =+M15*10% -> 1194772 | O15: =+I15 -> 10220190 | P15: 0 | Q15: =+M15-N15-O15-P15 -> 532758
B16: MARZO
F17: SUBVENCION | G17: SUBVENCION | H17: =SUBVENCION!G11+SUBVENCION!H11 -> 11489045 | J17: =+J15+H17-I17 -> 15932714 | L17: MARZO | M17: INGRESOS | N17: 10% ADM | O17: RR.HH. | P17: BNS Y SERV | Q17: SALDO
F18: REMUNERACIONES | G18: REMUNERACIONES | I18: 9348835 | J18: =+J17+H18-I18 -> 6583878.5 | M18: =+H17 -> 11489045 | N18: =+M18*10% -> 1148904.5 | O18: =+I18 -> 9348835 | P18: =I19+I20+I21+I22+I23+I24+I25+I26 -> 1422665 | Q18: =+M18-N18-O18-P18 -> -431359.5
B19: 46086 | C19: 5 | D19: 63 | E19: 569 | F19: MATERIALES OFICINA | G19: MATERIALES OFICINA | I19: 208131 | J19: =+J18+H19-I19 -> 6375747.5
B20: 46087 | C20: 6 | D20: 64 | E20: 583 | F20: MATERIALES ENSEÑANZA | G20: MATERIALES ENSEÑANZA | I20: 207740 | J20: =+J19+H20-I20 -> 6168007.5
B21: 46097 | C21: 9 | D21: 121 | E21: 571 | F21: MATERIALES ENSEÑANZA | G21: MATERIALES ENSEÑANZA | I21: 203659 | J21: =+J20+H21-I21 -> 5964348.5
B22: 46093 | C22: 7 | D22: 129 | E22: 392 | F22: MATERIALES ENSEÑANZA | G22: LIBRERÍA | I22: 208000 | J22: =+J21+H22-I22 -> 5756348.5
B23: 46097 | C23: 8 | D23: 128 | E23: 396 | F23: EQUIPO OFICINA | G23: IMPRESORA | I23: 199990 | J23: =+J22+H23-I23 -> 5556358.5
B24: 46100 | C24: 10 | D24: 143 | E24: 384 | F24: INSUMO COMPUTACIONALES | G24: TONER | I24: 195636 | J24: =+J23+H24-I24 -> 5360722.5
B25: 46104 | C25: 11 | D25: 207-208 | E25: 714 | F25: MATERIALES ENSEÑANZA | G25: JUEGO DIDACTICOS | I25: 199509 | J25: =+J24+H25-I25 -> 5161213.5
J26: =+J25+H26-I26 -> 5161213.5
J27: =+J26+H27-I27 -> 5161213.5
B28: ABRIL
F29: SUBVENCION | G29: SUBVENCION | H29: =SUBVENCION!I11+SUBVENCION!J11 -> 12555792 | J29: =+J27+H29-I29 -> 17717006 | L29: ABRIL | M29: INGRESOS | N29: 10% ADM | O29: RR.HH. | P29: BNS Y SERV | Q29: SALDO
F30: REMUNERACIONES | G30: REMUNERACIONES | I30: 9382193 | J30: =+J29+H30-I30 -> 8334812.5 | M30: =+H29 -> 12555792 | N30: =+M30*10% -> 1255579.2 | O30: =+I30 -> 9382193 | P30: =I31+I32+I33+I34 -> 1076048 | Q30: =+M30-N30-O30-P30 -> 841971.8
B31: 46113 | C31: 13 | D31: 209 | E31: 701 | F31: TEXTILES | G31: TEXTILES | I31: 207098 | J31: =+J30+H31-I31 -> 8127714.5
B32: 46114 | C32: 16 | D32: 2321-110-AG26 | E32: 775 | F32: INSUMO COMPUTACIONALES | G32: INSUMO COMPUTACIONALES | I32: 452200 | J32: =+J31+H32-I32 -> 7675514.5
B33: 46114 | C33: 14 | D33: 225 | E33: 572 | F33: MATERIALES ENSEÑANZA | G33: MATERIALES ENSEÑANZA | I33: 208500 | J33: =+J32+H33-I33 -> 7467014.5
B34: 46114 | C34: 15 | D34: 226 | E34: 613 | F34: MATERIALES ENSEÑANZA | G34: MATERIALES ENSEÑANZA | I34: 208250 | J34: =+J33+H34-I34 -> 7258764.5
B35: MAYO
F36: SUBVENCION | G36: SUBVENCION | H36: =SUBVENCION!K11+SUBVENCION!L11 -> 12345924 | J36: =+J34+H36-I36 -> 19604688 | L36: MAYO | M36: INGRESOS | N36: 10% ADM | O36: RR.HH. | P36: BNS Y SERV | Q36: SALDO
F37: REMUNERACIONES | G37: REMUNERACIONES | I37: 9373972 | J37: =+J36+H37-I37 -> 10230716 | M37: =+H36 -> 12345924 | N37: =+M37*10% -> 1234592.4 | O37: =+I37 -> 9373972 | P37: =I38+I39+I40+I41+I42+I43+I44+I45+I46 -> 2358614 | Q37: =+M37-N37-O37-P37 -> -621254.4
B38: 46146 | C38: 21 | D38: 406 | E38: 977 | F38: MATERIALES ENSEÑANZA | G38: LIBRERÍA | I38: 74300 | J38: =+J37+H38-I38 -> 10156416
B39: 46146 | C39: 22 | D39: 407 | E39: 960 | F39: MATERIALES ENSEÑANZA | G39: LIBRERÍA | I39: =152844+56095 -> 208939 | J39: =+J38+H39-I39 -> 9947477.5
I40: 180900 | J40: =+J39+H40-I40 -> 9766577.5
B41: 46146 | C41: 24-25 | D41: 409-410 | E41: 885 | F41: MATERIALES ENSEÑANZA | G41: LIBRERÍA | I41: 150170 | J41: =+J40+H41-I41 -> 9616407.5
...

Sheet E-414
B2: UNIDAD DE FINANZAS DAEM
B3: LEY SEP
B4: ESCUELA: E-414 MANUEL DE SALAS - RBD 3481
B5: DIRECTOR: CARLOS ASBUN SEPULVEDA
B6: SECTOR:
B7: RBD: 3481
B8: FECHA | C8: SOL | D8: OC | E8: DP | F8: CATEGORIA | G8: DETALLE | H8: INGRESOS | I8: GASTOS | J8: SALDO
G9: SALDO 2025 | H9: 30224473 | J9: =+H9-I9 -> 30224473
B10: ENERO
F11: SUBVENCION | G11: SUBVENCION | H11: =SUBVENCION!C5+SUBVENCION!D5 -> 24238665 | J11: =+J9+H11-I11 -> 54463138 | L11: ENERO | M11: INGRESOS | N11: 10% ADM | O11: RR.HH. | P11: BNS Y SERV | Q11: SALDO
F12: REMUNERACIONES | G12: REMUNERACIONES | I12: 15695889 | J12: =+J11+H12-I12 -> 38767249 | M12: =+H11 -> 24238665 | N12: =+M12*10% -> 2423866.5 | O12: =+I12 -> 15695889 | P12: =I13+I14+I15+I16+I17+I18+I19 -> 15104547 | Q12: =+M12-N12-O12-P12 -> -8985637.5
B13: 45966 | C13: 431 | D13: 2321-445-AG25 | E13: 15 | F13: COLACIONES | G13: COLACIONES | I13: 789565 | J13: =+J12+H13-I13 -> 37977684
B14: 45973 | C14: 434 | D14: 2321-477-AG25 | E14: 16 | F14: TRASPORTE | G14: TRASLADO | I14: 319800 | J14: =+J13+H14-I14 -> 37657884
B15: 45989 | C15: 455 | D15: 2321-480-AG25 | E15: 167 | F15: MATERIAL ENSEÑANZA | G15: LIBROS | I15: 2578106 | J15: =+J14+H15-I15 -> 35079778 | K15: =I13+I14+I15+I16+I17+I18 -> 14610038
B16: 45989 | C16: 459 | D16: 2321-478-AG25 | E16: 164 | F16: MATERIALE ENSEÑANZA | G16: MATERIALE ENSEÑANZA | I16: 521238 | J16: =+J15+H16-I16 -> 34558540
B17: 45989 | C17: 458 | D17: 2321-4-AG26 | E17: 166 | F17: EQUIPO COMPUTACIONEALES | G17: EQUIPO COMPUTACIONEALES | I17: 6490001 | J17: =+J16+H17-I17 -> 28068539
B18: 45981 | C18: 445 | D18: 2321-2-AG26 | E18: 393 | F18: MATERIAL ENSEÑANZA | G18: LIBRERÍA | I18: 3911328 | J18: =+J17+H18-I18 -> 24157211
E19: 55 | F19: INTERNET | G19: INTERNET | I19: 494509 | J19: =+J18+H19-I19 -> 23662702
J20: =+J19+H20-I20 -> 23662702
B21: FEBRERO
F22: SUBVENCION | G22: SUBVENCION | H22: =SUBVENCION!E5+SUBVENCION!F5 -> 25683022 | J22: =+J20+H22-I22 -> 49345724 | L22: FEBRERO | M22: INGRESOS | N22: 10% ADM | O22: RR.HH. | P22: BNS Y SERV | Q22: SALDO
F23: REMUNERACIONES | G23: REMUNERACIONES | I23: 17093190 | J23: =+J22+H23-I23 -> 32252534 | M23: =+H22 -> 25683022 | N23: =+M23*10% -> 2568302.2 | O23: =+I23 -> 17093190 | P23: =I24+I25+I26 -> 494206 | Q23: =+M23-N23-O23-P23 -> 5527323.8
E24: 161 | F24: INTERNET | G24: INTERNET | I24: 494206 | J24: =+J23+H24-I24 -> 31758328
J25: =+J24+H25-I25 -> 31758328
J26: =+J25+H26-I26 -> 31758328
J27: =+J26+H27-I27 -> 31758328 | N27: =M27*10% -> 0
B28: MARZO
F29: SUBVENCION | G29: SUBVENCION | H29: 15571734 | J29: =+J27+H29-I29 -> 47330062 | L29: MARZO | M29: INGRESOS | N29: 10% ADM | O29: RR.HH. | P29: BNS Y SERV | Q29: SALDO
F30: REMUNERACIONES | G30: REMUNERACIONES | I30: 15571734 | J30: =+J29+H30-I30 -> 31758328 | M30: =+H29 -> 15571734 | N30: =+M30*10% -> 1557173.4 | O30: =+I30 -> 15571734 | P30: =I31+I32+I33+I34+I35+I36+I37+I38+I39+I40+I41+I42 -> 9375798 | Q30: =+M30-N30-O30-P30 -> -10932971
F31: FONDO A RENDIR | G31: FONDO A RENDIR | I31: 698890 | J31: =+J30+H31-I31 -> 31059438
B32: 46090 | C32: 6 | D32: 2321-153-TD26 | E32: 1205 | F32: LICENCIA SOFWARE | G32: LICENCIA SOFWARE | I32: 5236000 | J32: =+J31+H32-I32 -> 25823438
B33: 46092 | C33: 8 | D33: 85 | E33: 273 | F33: VESTUARIO | G33: VESTUARIO DEPORTIVO | I33: 124950 | J33: =+J32+H33-I33 -> 25698488
B34: 46092 | C34: 7 | D34: 86 | E34: 383 | F34: MATERIALES ENSEÑANZA | G34: LIBRERÍA | I34: 204600 | J34: =+J33+H34-I34 -> 25493888
B35: 46090 | C35: 4 | D35: 88 | E35: 376 | F35: INSUMO COMPUTACIONES | G35: TAMBOR | I35: 186002 | J35: =+J34+H35-I35 -> 25307886
B36: 46090 | C36: 5 | D36: 87 | E36: 274 | F36: GASTOS MENORES | G36: ALARGADORES | I36: 207603 | J36: =+J35+H36-I36 -> 25100283
E37: 293 | F37: INTERNET | G37: INTERNET | I37: 495360 | J37: =+J36+H37-I37 -> 24604923
E38: 292 | F38: FONDO A RENDIR | G38: FONDO A RENDIR | I38: 698890 | J38: =+J37+H38-I38 -> 23906033
B39: 46106 | C39: 12 | D39: 172 | E39: 600 | F39: MATERIALES ENSEÑANZA | G39: INSUMO GASTRONOMICOS | I39: 209492 | J39: =+J38+H39-I39 -> 23696541
B40: 46106 | C40: 13 | D40: 2321-158-AG236 | E40: 875 | F40: EQUIPO DE OFICINA | G40: LAPTOP | I40: 899990 | J40: =+J39+H40-I40 -> 22796551
B41: 46106 | C41: 14 | D41: 173 | E41: 422 | F41: MATERIALES ENSEÑANZA | G41: JUEGO AJEDREZ | I41: 206999 | J41: =+J40+H41-I41 -> 22589552
...

Sheet G-416
B2: UNIDAD DE FINANZAS DAEM
B3: LEY SEP
B4: ESCUELA: G-416 CANDELARIA PEREZ
B5: DIRECTOR: PAULINA TOLEDO HERNANDEZ
B6: SECTOR:
B7: RBD: 3517
B8: FECHA | C8: SOL | D8: OC | E8: DP | F8: CATEGORIA | G8: DETALLE | H8: INGRESOS | I8: GASTOS | J8: SALDO
G9: SALDO SEP 2025 | H9: 5512238 | J9: =+H9-I9 -> 5512238
B10: ENERO
F11: SUBVENCION | G11: SUBVENCION | H11: =SUBVENCION!C18+SUBVENCION!D18 -> 5498136 | J11: =+H11-I11+J9 -> 11010374 | L11: INGRESOS | M11: 10% ADM | N11: RR.HH. | O11: BNS Y SERV | P11: SALDO
F12: REMUNERACIONES | G12: REMUNERACIONES | I12: 3558445 | J12: =+J11+H12-I12 -> 7451929 | L12: =H11 -> 5498136 | M12: =L12*10% -> 549813.6 | N12: =I12 -> 3558445 | O12: =I13+I14+I15+I16+I17 -> 1284578 | P12: =L12-M12-N12-O12 -> 105299.4
B13: 45952 | C13: 137 | D13: 2321-459-AG25 | E13: 14 | F13: MATERIALES OFICINA | G13: LIBRERÍA | I13: 1263676 | J13: =+J12+H13-I13 -> 6188253
E14: 12 | F14: INTERNET | G14: INTERNET | I14: 20902 | J14: =+J13+H14-I14 -> 6167351
J15: =+J14+H15-I15 -> 6167351
J16: =+J15+H16-I16 -> 6167351
J17: =+J16+H17-I17 -> 6167351
B18: FEBRERO
F19: SUBVENCION | G19: SUBVENCION | H19: =SUBVENCION!E18+SUBVENCION!F18 -> 5832393 | J19: =+J17+H19-I19 -> 11999744 | L19: INGRESOS | M19: 10% ADM | N19: RR.HH. | O19: BNS Y SERV | P19: SALDO
F20: REMUNERACIONES | G20: REMUNERACIONES | I20: 3558445 | J20: =+J19+H20-I20 -> 8441299 | L20: =H19 -> 5832393 | M20: =L20*10% -> 583239.3 | N20: =I20 -> 3558445 | O20: =I21 -> 20766 | P20: =L20-M20-N20-O20 -> 1669942.7
E21: 130 | F21: INTERNET | G21: INTERNET | I21: 20766 | J21: =+J20+H21-I21 -> 8420533
B22: MARZO
F23: SUBVENCION | G23: SUBVENCION | H23: =SUBVENCION!G18+SUBVENCION!H18 -> 5608104 | J23: =+J21+H23-I23 -> 14028637
F24: REMUNERACIONES | G24: REMUNERACIONES | I24: 3065789 | J24: =+J23+H24-I24 -> 10962848 | L24: INGRESOS | M24: 10% ADM | N24: RR.HH. | O24: BNS Y SERV | P24: SALDO
B25: 46090 | C25: 3 | D25: 69 | E25: 272 | F25: MATERIALES ENSEÑANZA | G25: MATERIALES ENSEÑANZA | I25: 200000 | J25: =+J24+H25-I25 -> 10762848 | L25: =H23 -> 5608104 | M25: =L25*10% -> 560810.4 | N25: =I24 -> 3065789 | O25: =I25+I26+I27+I28+I29++I30+I31+I32+I33 -> 1607660 | P25: =L25-M25-N25-O25 -> 373844.6
B26: 46097 | C26: 5 | D26: 120 | E26: 382 | F26: MATERIALES DE ENSEÑANZA | G26: LIBROS | I26: 209651 | J26: =+J25+H26-I26 -> 10553197
E27: 222 | F27: INTERNET | G27: INTERNET | I27: 20766 | J27: =+J26+H27-I27 -> 10532431
B28: 46098 | C28: 7 | D28: 138 | E28: 404 | F28: MATERIALES ENSEÑANZA | G28: SET MALLA TALLER DEPORTE | I28: 44000 | J28: =+J27+H28-I28 -> 10488431
B29: 46097 | C29: 6 | D29: 139 | E29: 425 | F29: MATERIALES ENSEÑANZA | G29: MATERIALES ARTES | I29: 209000 | J29: =+J28+H29-I29 -> 10279431
B30: 23-03-206 | C30: 9 | D30: 2321-120-AG26 | E30: 778 | F30: BATERIAS EVALUA | G30: BATERIAS EVALUA | I30: 494624 | J30: =+J29+H30-I30 -> 9784807
B31: 46104 | C31: 10 | D31: 155 | E31: 607 | F31: MATERIALES ENSEÑANZA | G31: LIBRERÍA | I31: 194780 | J31: =+J30+H31-I31 -> 9590027
B32: 46106 | C32: 12 | D32: 171 | E32: 407 | F32: INSUMO COMPUTACIONALES | G32: TINTAS | I32: 207840 | J32: =+J31+H32-I32 -> 9382187
B33: 45741 | C33: 13 | D33: 175 | E33: 386 | F33: PREMIOS | G33: PREMIOS | I33: 26999 | J33: =+J32+H33-I33 -> 9355188
B34: ABRIL
F35: SUBVENCION | G35: SUBVENCION | H35: =SUBVENCION!I18+SUBVENCION!J18 -> 5678407 | J35: =+J33+H35-I35 -> 15033595
F36: REMUNERACIONES | G36: REMUNERACIONES | I36: 2902406 | J36: =+J35+H36-I36 -> 12131189 | L36: INGRESOS | M36: 10% ADM | N36: RR.HH. | O36: BNS Y SERV | P36: SALDO
E37: 350 | F37: INTERNET | G37: INTERNET | I37: 20968 | J37: =+J36+H37-I37 -> 12110221 | L37: =H35 -> 5678407 | M37: =L37*10% -> 567840.7 | N37: =I36 -> 2902406 | O37: =I37+I38+I39+I40+I41+I42+I43+I44+I45+I46 -> 1791909 | P37: =L37-M37-N37-O37 -> 416251.3
B38: 46114 | C38: 15 | D38: 218 | E38: 408 | F38: MANTENCION EQUIPO | G38: MANTENCION EQUIPO | I38: 194999 | J38: =+J37+H38-I38 -> 11915222
B39: 46126 | C39: 22 | D39: 2321-123-AG26 | E39: 777 | F39: COLACIONES | G39: COLACIONES | I39: 390737 | J39: =+J38+H39-I39 -> 11524485
B40: 46126 | C40: 21 | D40: 2321-135-AG26 | E40: 961 | F40: MOBILIARIO | G40: BANCA CAMARIN | I40: 380800 | J40: =+J39+H40-I40 -> 11143685
B41: 46126 | C41: 20 | D41: 290 | E41: 601 | F41: TRASNPORTE | G41: TRASLADO | I41: 207000 | J41: =+J40+H41-I41 -> 10936685
...

Sheet E-417
B2: UNIDAD DE FINANZAS DAEM
B3: LEY SEP
B4: ESCUELA: E-417 JUSTA NARVAEZ RBD 3482
B5: DIRECTOR: FERNANDO JARAMILLO
B6: SECTOR:
B7: RBD: 3482
B8: FECHA | C8: SOL | D8: OC | E8: DP | F8: CATEGORIA | G8: DETALLE | H8: INGRESOS | I8: GASTOS | J8: SALDO
G9: SALDO SEP 2025 | H9: ='[1]E-417'!$J$149 -> 5843683 | J9: =+H9-I9 -> 5843683
B10: ENERO
F11: SUBVENCION | G11: SUBVENCION | H11: =SUBVENCION!C6+SUBVENCION!D6 -> 14182089 | J11: =+J9+H11-I11 -> 20025772 | K11: ENERO | L11: INGRESOS | M11: 10% ADM | N11: RR.HH. | O11: BNS Y SERV | P11: SALDO
F12: REMUNERACIONES | G12: REMUNERACIONES | I12: 10527943 | J12: =+J11+H12-I12 -> 9497829 | L12: =+H11 -> 14182089 | M12: =+L12*10% -> 1418208.9 | N12: =+I12 -> 10527943 | O12: =I13+I14 -> 55462 | P12: =+L12-M12-N12-O12 -> 2180475.1
E13: 11 | F13: INTERNET | G13: INTERNET | I13: 27731 | J13: =+J12+H13-I13 -> 9470098
E14: 92 | F14: INTERNET | G14: INTERNET | I14: 27731 | J14: =+J13+H14-I14 -> 9442367
B15: FEBRERO
F16: SUBVENCION | G16: SUBVENCION | H16: =SUBVENCION!E6+SUBVENCION!F6 -> 14313112 | J16: =+J14+H16-I16 -> 23755479 | K16: FEBRERO | L16: INGRESOS | M16: 10% ADM | N16: RR.HH. | O16: BNS Y SERV | P16: SALDO
F17: REMUNERACIONES | G17: REMUNERACIONES | I17: 11157706 | J17: =+J16+H17-I17 -> 12597773 | L17: =+H16 -> 14313112 | M17: =+L17*10% -> 1431311.2 | N17: =+I17 -> 11157706 | O17: =+I18+I19 -> 1827772 | P17: =+L17-M17-N17-O17 -> -103677.2
B18: 46079 | C18: 1 | D18: 2321-279-TD26 | E18: PP | F18: PLATAFORMA | G18: PLATAFORMA | I18: 1800000 | J18: =+J17+H18-I18 -> 10797773
E19: 163 | F19: INTERNET | G19: INTERNET | I19: 27772 | J19: =+J18+H19-I19 -> 10770001
J20: =+J19+H20-I20 -> 10770001
B21: MARZO
F22: SUBVENCION | G22: SUBVENCION | H22: =SUBVENCION!G6+SUBVENCION!H6 -> 14225576 | J22: =+J20+H22-I22 -> 24995577 | K22: MARZO | L22: INGRESOS | M22: 10% ADM | N22: RR.HH. | O22: BNS Y SERV | P22: SALDO
F23: REMUNERACIONES | G23: REMUNERACIONES | I23: 9385199 | J23: =+J22+H23-I23 -> 15610378 | L23: =+H22 -> 14225576 | M23: =+L23*10% -> 1422557.6 | N23: =+I23 -> 9385199 | O23: =I24+I25+I26+I27+I28+I29+I30+I31+I32+I33+I34+I35 -> 2289316 | P23: =+L23-M23-N23-O23 -> 1128503.4
B24: 46084 | C24: 5 | D24: 25 | E24: 575 | F24: MATERIALES DE ENSEÑANZA | G24: LIBRERÍA | I24: 205459 | J24: =+J23+H24-I24 -> 15404919
B25: 46084 | C25: 6 | D25: 26 | E25: 257 | F25: MATERIALES DE ENSEÑANZA | G25: LIBRERÍA | I25: 205500 | J25: =+J24+H25-I25 -> 15199419
B26: 46085 | C26: 12 | D26: 40 | E26: 574 | F26: INSUMO COMPUTACIONALES | G26: TINTAS | I26: 205555 | J26: =+J25+H26-I26 -> 14993864
B27: 46087 | C27: 16 | D27: 58 | E27: 380 | F27: MATERIALES DE ENSEÑANZA | G27: MATERIALES DIDACTICOS | I27: 191860 | J27: =+J26+H27-I27 -> 14802004
B28: 46090 | C28: 17 | D28: 59 | E28: 424 | F28: COLACIONES | G28: COLACIONES | I28: 208000 | J28: =+J27+H28-I28 -> 14594004
B29: 46099 | C29: 18 | D29: 134 | E29: 376 | F29: INSUMO COMPUTACIONALES | G29: TINTAS | I29: 208803 | J29: =+J28+H29-I29 -> 14385201
B30: 46099 | C30: 19 | D30: 135 | E30: 385 | F30: GASTOS MENORES | G30: LIENZO- PENDON - PIOCHA | I30: 208559 | J30: =+J29+H30-I30 -> 14176642
F31: INTERNET | G31: INTERNET | I31: 27731 | J31: =+J30+H31-I31 -> 14148911
B32: 46101 | C32: 20 | D32: 177 | E32: 374 | F32: COLACIONES | G32: COLACIONES | I32: 207970 | J32: =+J31+H32-I32 -> 13940941
B33: 46107 | C33: 21 | D33: 178 | E33: 379 | F33: MATERIALES DE ENSEÑANZA | G33: INSTRUMENTO MUSICALES | I33: 202889 | J33: =+J32+H33-I33 -> 13738052
B34: 46107 | C34: 23 | D34: 179 | E34: 426 | F34: COLACIONES | G34: COLACIONES | I34: 208000 | J34: =+J33+H34-I34 -> 13530052
B35: 46108 | C35: 24 | D35: 180 | E35: 408 | F35: EQUIPO DE OFICINA | G35: IMPRESORA | I35: 208990 | J35: =+J34+H35-I35 -> 13321062
B36: ABRIL
F37: SUBVENCION | G37: SUBVENCION | H37: =SUBVENCION!I6+SUBVENCION!J6 -> 13989832 | J37: =+J35+H37-I37 -> 27310894 | K37: ABRIL | L37: INGRESOS | M37: 10% ADM | N37: RR.HH. | O37: BNS Y SERV | P37: SALDO
F38: REMUNERACIONES | G38: REMUNERACIONES | I38: 10858560 | J38: =+J37+H38-I38 -> 16452334 | L38: =+H37 -> 13989832 | M38: =+L38*10% -> 1398983.2 | N38: =+I38 -> 10858560 | O38: =I39+I40+I41+I42+I43+I44+I45+I46+I47+I48+I49 -> 2603700 | P38: =+L38-M38-N38-O38 -> -871411.2
B39: 46119 | C39: 29 | D39: 259 | E39: 567 | F39: TRANSPORTE | G39: TRASLADO | I39: 150000 | J39: =+J38+H39-I39 -> 16302334
B40: 46121 | C40: 30 | D40: 295 | E40: 599 | F40: COLACIONES | G40: COLACIONES | I40: 209080 | J40: =+J39+H40-I40 -> 16093254
B41: 46128 | C41: 35 | D41: 2321-240-AG26 | E41: 1349 | F41: EQUIPO DE OFICINA | G41: PROYECTOR | I41: 547138 | J41: =+J40+H41-I41 -> 15546116
...

Sheet G-418
B2: UNIDAD DE FINANZAS DAEM
B3: LEY SEP
B4: ESCUELA: G-418 MARIANO EGAÑA
B5: DIRECTOR: DOLY ROJAS FUENTES
B6: SECTOR:
B7: RBD: 3518
B8: FECHA | C8: SOL | D8: OC | E8: DP | F8: CATEGORIA | G8: DETALLE | H8: INGRESOS | I8: GASTOS | J8: SALDO
G9: SALDO 2025 | H9: -177954 | J9: =+H9-I9 -> -177954
B10: ENERO | K10: ENERO | L10: INGRESOS | M10: 10% ADM | N10: RR.HH. | O10: BNS Y SERV | P10: SALDO
F11: SUBVENCION | G11: SUBVENCION | H11: =SUBVENCION!C19+SUBVENCION!D19 -> 655614 | J11: =+J9+H11-I11 -> 477660 | L11: =H11 -> 655614 | M11: =L11*10% -> 65561.4 | P11: =L11-M11 -> 590052.6
B12: FEBRERO | K12: FEBRERO | L12: INGRESOS | M12: 10% ADM | N12: RR.HH. | O12: BNS Y SERV | P12: SALDO
F13: SUBVENCION | G13: SUBVENCION | H13: =SUBVENCION!E19+SUBVENCION!F19 -> 694449 | J13: =+J11+H13-I13 -> 1172109 | L13: =H13 -> 694449 | M13: =L13*10% -> 69444.9 | P13: =L13-M13 -> 625004.1
B14: MARZO
F15: SUBVENCION | G15: SUBVENCION | H15: =SUBVENCION!G19+SUBVENCION!H19 -> 668721 | J15: =+J13+H15-I15 -> 1840830 | K15: MARZO | L15: INGRESOS | M15: 10% ADM | N15: RR.HH. | O15: BNS Y SERV | P15: SALDO
B16: 46087 | C16: 1 | D16: 55 | E16: 340 | F16: VESTUARIO | G16: VESTUARIO DEPORTIVO | I16: 205000 | J16: =+J15+H16-I16 -> 1635830 | L16: =H15 -> 668721 | M16: =H15*10% -> 66872.1 | N16: 0 | O16: =I16+I17+I18 -> 589799 | P16: =L16-M16-O16 -> 12049.9
B17: 46087 | C17: 2 | D17: 60 | E17: 377 | F17: EQUIPO DE OFICNA | G17: IMPRESORA | I17: 180900 | J17: =+J16+H17-I17 -> 1454930
B18: 46087 | C18: 3 | D18: 73 | E18: 383 | F18: MATERIALES ENSEÑANZA | G18: LIBRERÍA | I18: 203899 | J18: =+J17+H18-I18 -> 1251031
J19: =+J18+H19-I19 -> 1251031
B20: ABRIL
F21: SUBVENCION | G21: SUBVENCION | H21: =SUBVENCION!I19+SUBVENCION!J19 -> 869820 | J21: =+J19+H21-I21 -> 2120851 | K21: ABRIL | L21: INGRESOS | M21: 10% ADM | N21: RR.HH. | O21: BNS Y SERV | P21: SALDO
B22: 46114 | C22: 5 | D22: 213 | E22: 410 | F22: MATERIALES ENSEÑANZA | G22: MATERIALES ENSEÑANZA | I22: 209540 | J22: =+J21+H22-I22 -> 1911311 | L22: =H21 -> 869820 | M22: =L22*10% -> 86982 | O22: =I22+I23+I24+I25+I26+I27+I28+I29+I30 -> 1806983 | P22: =L22-M22-O22 -> -1024145
B23: 46125 | C23: 8 | D23: 283 | E23: 636 | F23: MATERIALES ENSEÑANZA | G23: MATERIALES ENSEÑANZA | I23: 207655 | J23: =+J22+H23-I23 -> 1703656
B24: 46125 | C24: 7 | D24: 282 | E24: 702 | F24: OTROS SERVICIOS | G24: DIFUCIIÓN | I24: 178500 | J24: =+J23+H24-I24 -> 1525156
B25: 46127 | C25: 6 | D25: 281 | E25: 642 | F25: MATERIALES ENSEÑANZA | G25: LIBRERÍA | I25: 209000 | J25: =+J24+H25-I25 -> 1316156
B26: 46127 | C26: 11 | D26: 297-298 | E26: 599 | F26: COLACIONES | G26: COLACIONES | I26: 200640 | J26: =+J25+H26-I26 -> 1115516
B27: 46127 | C27: 9 | D27: 296 | E27: 750 | F27: MATERIALES ENSEÑANZA | G27: MATERIALES ENSEÑANZA | I27: 197008 | J27: =+J26+H27-I27 -> 918508
B28: 46136 | C28: 12 | D28: 351 | E28: 727 | F28: VESTUARIO | G28: VESTUARIO DEPORTIVO | I28: 205000 | J28: =+J27+H28-I28 -> 713508
B29: 46136 | C29: 14 | D29: 352 | E29: 583 | F29: MATERIALES ENSEÑANZA | G29: MATERIALES ENSEÑANZA | I29: 209640 | J29: =+J28+H29-I29 -> 503868
B30: 46136 | C30: 13 | D30: 353 | E30: 696 | F30: INSUMO COMPUTRACIONALES | G30: INSUMO COMPUTRACIONALES | I30: 190000 | J30: =+J29+H30-I30 -> 313868
J31: =+J30+H31-I31 -> 313868
B32: MAYO
F33: SUBVENCION | G33: SUBVENCION | H33: 869820 | J33: =+J31+H33-I33 -> 1183688 | K33: MAYO | L33: INGRESOS | M33: 10% ADM | N33: RR.HH. | O33: BNS Y SERV | P33: SALDO
B34: 46149 | C34: 17 | D34: 405 | E34: 746 | F34: MATERIALES ENSEÑANZA | G34: LIBRERÍA | I34: 211750 | J34: =+J33+H34-I34 -> 971938 | L34: =H33 -> 869820 | M34: =L34*10% -> 86982 | O34: =I34+I35+I36 -> 629050 | P34: =H33-M34-O34 -> 153788
B35: 46153 | C35: 18 | D35: 429 | E35: 747 | F35: COLACIONES | G35: COLACIONES | I35: 209050 | J35: =+J34+H35-I35 -> 762888
B36: 46149 | C36: 15 | D36: 439 | E36: 761 | F36: OTROS SERVICIOS | G36: OTROS SERVICIOS | I36: 208250 | J36: =+J35+H36-I36 -> 554638
B37: JUNIO
F38: SUBVENCION | G38: SUBVENCION | H38: =SUBVENCION!M19+SUBVENCION!N19 -> 1293635 | J38: =+J36+H38-I38 -> 1848273 | K38: JUNIO | L38: INGRESOS | M38: 10% ADM | N38: RR.HH. | O38: BNS Y SERV | P38: SALDO
B39: 46177 | C39: 19 | D39: 540 | E39: 881 | F39: VESTUARIO | G39: VESTUARIO DEPORTIVO | I39: 205000 | J39: =+J38+H39-I39 -> 1643273 | L39: =H38 -> 1293635 | M39: =L39*10% -> 129363.5 | O39: =I39+I40+I41+I42 -> 847600 | P39: =L39-M39-O39 -> 316671.5
B40: 46184 | C40: 21 | D40: 567 | F40: MATERIALES ENSEÑANZA | G40: MATERIALES ENSEÑANZA | I40: 214400 | J40: =+J39+H40-I40 -> 1428873
B41: 46185 | C41: 22 | D41: 579 | E41: 1159 | F41: PREMIOS | G41: PREMIOS | I41: 214200 | J41: =+J40+H41-I41 -> 1214673
...

Sheet G-419
B3: LEY SEP
B4: Escuela: G-419 MARIANO LATORRE RBD 3520
B5: Director: PEDRO CACERES
B6: FECHA | C6: SOL | D6: OC | E6: DP | F6: CATEGORIA | G6: DETALLE | H6: INGRESOS | I6: GASTOS | J6: SALDO
G7: SALDO 2025 | H7: 5298959 | J7: =+H7-I7 -> 5298959
B8: ENERO | K8: ENERO | L8: INGRESOS | M8: 10% ADM | N8: RR.HH. | O8: BNS Y SERV | P8: SALDO
F9: SUBVENCION | G9: SUBVENCION | H9: =SUBVENCION!C20+SUBVENCION!D20 -> 1225815 | J9: =+J7+H9-I9 -> 6524774 | L9: =H9 -> 1225815 | M9: =L9*10% -> 122581.5 | N9: =I10 -> 203856 | O9: =I11 -> 0 | P9: =L9-M9-N9-O9 -> 899377.5
F10: REMUNERACIONES | G10: REMUNERACIONES | I10: 203856 | J10: =+J9+H10-I10 -> 6320918
J11: =+J10+H11-I11 -> 6320918
B12: FEBRERO
F13: SUBVENCION | G13: SUBVENCION | H13: =SUBVENCION!E20+SUBVENCION!F20 -> 1236346 | J13: =+J11+H13-I13 -> 7557264 | K13: FEBRERO | L13: INGRESOS | M13: 10% ADM | N13: RR.HH. | O13: BNS Y SERV | P13: SALDO
F14: REMUNERACIONES | G14: REMUNERACIONES | I14: 207948 | J14: =+J13+H14-I14 -> 7349316 | L14: =H13 -> 1236346 | M14: =L14*10% -> 123634.6 | N14: =I14 -> 207948 | O14: 0 | P14: =L14-M14-N14 -> 904763.4
B15: MARZO
F16: SUBVENCION | G16: SUBVENCION | H16: =SUBVENCION!G20+SUBVENCION!H20 -> 1229349 | J16: =+J14+H16-I16 -> 8578665 | K16: MARZO | L16: INGRESOS | M16: 10% ADM | N16: RR.HH. | O16: BNS Y SERV | P16: SALDO
F17: REMUNERACIONES | G17: REMUNERACIONES | I17: 207948 | J17: =+J16+H17-I17 -> 8370717 | L17: =H16 -> 1229349 | M17: =L17*10% -> 122934.9 | N17: =I17 -> 207948 | O17: =I18+I19+I20+I21+I22+I23+I24 -> 1394372 | P17: =L17-M17-N17-O17 -> -495905.9
B18: 46086 | C18: 5 | D18: 70 | E18: 391 | F18: MATERIALES ENSEÑANZA | G18: LIBRERÍA | I18: 204536 | J18: =+J17+H18-I18 -> 8166181
B19: 45725 | C19: 4 | D19: 71 | E19: 382 | F19: MATERIALES ENSEÑANZA | G19: LIBRERÍA | I19: 208430 | J19: =+J18+H19-I19 -> 7957751
B20: 46086 | C20: 2 | D20: 83 | E20: 385 | F20: VESTUARIO | G20: VESTUARIO DEPORTIVO | I20: 208548 | J20: =+J19+H20-I20 -> 7749203
B21: 46108 | C21: 6 | D21: 181 | E21: 600 | F21: COLACIONES | G21: COLACIONES | I21: 208678 | J21: =+J20+H21-I21 -> 7540525
B22: 46110 | C22: 7 | D22: 200 | E22: 747 | F22: COLACIONES | G22: COLACIONES | I22: 172810 | J22: =+J21+H22-I22 -> 7367715
B23: 46110 | C23: 8 | D23: 201 | E23: 431 | F23: MATERIALES ENSEÑANZA | G23: LIBRERÍA | I23: 209300 | J23: =+J22+H23-I23 -> 7158415
B24: 46111 | C24: 12 | D24: 205 | E24: 430 | F24: GASTOS MENORES | G24: GASTOS MENORES | I24: 182070 | J24: =+J23+H24-I24 -> 6976345
J25: =+J24+H25-I25 -> 6976345
J26: =+J25+H26-I26 -> 6976345
B27: ABRIL
F28: SUBVENCION | G28: SUBVENCION | H28: =SUBVENCION!I20+SUBVENCION!J20 -> 1205332 | J28: =+J26+H28-I28 -> 8181677 | K28: ABRIL | L28: INGRESOS | M28: 10% ADM | N28: RR.HH. | O28: BNS Y SERV | P28: SALDO
F29: REMUNERACIONES | G29: REMUNERACIONES | I29: 208309 | J29: =+J28+H29-I29 -> 7973368 | L29: =H28 -> 1205332 | M29: =L29*10% -> 120533.2 | N29: =I29 -> 208309 | O29: =+I30+I31+I32+I33 -> 829042 | P29: =L29-M29-N29-O29 -> 47447.8
B30: 46113 | C30: 13 | D30: 210 | E30: 432 | F30: TRASLADO | G30: TRANSPORTE | I30: 207000 | J30: =+J29+H30-I30 -> 7766368
B31: 46128 | C31: 14 | D31: 293 | E31: 576 | F31: MATERIALES ENSEÑANZA | G31: LIBRERÍA | I31: 207000 | J31: =+J30+H31-I31 -> 7559368
B32: 46132 | C32: 15 | D32: 314 | E32: 600 | F32: COLACIONES | G32: COLACIONES | I32: 208678 | J32: =+J31+H32-I32 -> 7350690
B33: 46133 | C33: 16 | D33: 332 | E33: 599 | F33: COLACIONES | G33: COLACIONES | I33: 206364 | J33: =+J32+H33-I33 -> 7144326
J34: =+J33+H34-I34 -> 7144326
B35: MAYO
F36: SUBVENCION | G36: SUBVENCION | H36: =SUBVENCION!K20+SUBVENCION!L20 -> 1211485 | J36: =+J34+H36-I36 -> 8355811 | K36: MAYO | L36: INGRESOS | M36: 10% ADM | N36: RR.HH. | O36: BNS Y SERV | P36: SALDO
F37: REMUNERACIONES | G37: REMUNERACIONES | I37: 214858 | J37: =+J36+H37-I37 -> 8140953 | L37: =H36 -> 1211485 | M37: =L37*10% -> 121148.5 | N37: =I37 -> 214858 | O37: =I38+I39+I40 -> 211000 | P37: =L37-M37-N37-O37 -> 664478.5
B38: 46167 | C38: 17 | D38: 479 | F38: MATERIALES ENSEÑANZA | G38: LIBRERÍA | I38: 211000 | J38: =+J37+H38-I38 -> 7929953
J39: =+J38+H39-I39 -> 7929953
J40: =+J39+H40-I40 -> 7929953
B41: JUNIO
F42: SUBVENCION | G42: SUBVENCION | H42: =SUBVENCION!M20+SUBVENCION!N20 -> 1037348 | J42: =+J40+H42-I42 -> 8967301 | K42: JUNIO | L42: INGRESOS | M42: 10% ADM | N42: RR.HH. | O42: BNS Y SERV | P42: SALDO
...

Sheet E-424
B2: UNIDAD DE FINANZAS DAEM
B3: LEY SEP
B4: ESCUELA: E-424 GERONIMO LAGOS LISBOA
B5: DIRECTOR: PATRICIO YAÑEZ
B6: RBD: 3483
B7: SECTOR:
B8: FECHA | C8: SOL | D8: OC | E8: DP | F8: CATEGORIA | G8: DETALLE | H8: INGRESOS | I8: GASTOS | J8: SALDO
G9: SALDO SEP 2025 | H9: -2405121 | J9: =+H9-I9 -> -2405121
B10: ENERO
F11: SUBVENCION | G11: SUBVENCION | H11: =SUBVENCION!C7+SUBVENCION!D7 -> 36332097 | J11: =+H11 -> 36332097 | K11: ENERO | L11: INGRESOS | M11: 10% ADM | N11: RR.HH. | O11: BNS Y SERV | P11: SALDO
F12: REMUNERACIONES | G12: REMUNERACIONES | I12: 29886050 | J12: =+J11+H12-I12 -> 6446047 | L12: =H11 -> 36332097 | M12: =L12*10% -> 3633209.7 | N12: =I12 -> 29886050 | O12: =I13+I14 -> 486946 | P12: =L12-M12-N12-O12 -> 2325891.3
E13: 55 | F13: INTERNET | G13: INTERNET | I13: 486946 | J13: =+J12+H13-I13 -> 5959101
J14: =+J13+H14-I14 -> 5959101
B15: FEBRERO | R15: =P12+P17 -> 4035424.7
F16: SUBVENCION | G16: SUBVENCION | H16: =SUBVENCION!E7+SUBVENCION!F7 -> 38440236 | J16: =+J14+H16-I16 -> 44399337 | K16: FEBRERO | L16: INGRESOS | M16: 10% ADM | N16: RR.HH. | O16: BNS Y SERV | P16: SALDO
F17: REMUNERACIONES | G17: REMUNERACIONES | I17: 32400033 | J17: =+J16+H17-I17 -> 11999304 | L17: =H16 -> 38440236 | M17: =L17*10% -> 3844023.6 | N17: =I17 -> 32400033 | O17: =I18+I19+I20 -> 486646 | P17: =L17-M17-N17-O17 -> 1709533.4
E18: 161 | F18: INTERNET | G18: INTERNET | I18: 486646 | J18: =+J17+H18-I18 -> 11512658
J19: =+J18+H19-I19 -> 11512658
J20: =+J19+H20-I20 -> 11512658
B21: MARZO
F22: SUBVENCION | G22: SUBVENCION | H22: =SUBVENCION!G7+SUBVENCION!H7 -> 36993977 | J22: =+J20+H22-I22 -> 48506635 | K22: MARZO | L22: INGRESOS | M22: 10% ADM | N22: RR.HH. | O22: BNS Y SERV | P22: SALDO
F23: REMUNERACIONES | G23: REMUNERACIONES | I23: 25445960 | J23: =+J22+H23-I23 -> 23060675 | L23: =H22 -> 36993977 | M23: =L23*10% -> 3699397.7 | N23: =I23 -> 25445960 | O23: =SUM(I24:I32) -> 9706312 | P23: =L23-M23-N23-O23 -> -1857692.7
B24: 46090 | C24: 17 | D24: 82 | E24: 382 | F24: MATERIALE ENSEÑANZA | G24: LIBRERÍA | I24: 207960 | J24: =+J23+H24-I24 -> 22852715
B25: 46090 | C25: 18 | D25: 2321-69-AG26 | E25: 394 | F25: INSUMO COMPUTACIONEALES | G25: TINTAS - TONER | I25: 1900430 | J25: =+J24+H25-I25 -> 20952285
B26: 46091 | C26: 19 | D26: 103 | E26: 598 | F26: MATERIALES DE ENSEÑANZA | G26: LIBRERÍA | I26: 183297 | J26: =+J25+H26-I26 -> 20768988
B27: 46091 | C27: 20 | D27: 106 | E27: 598 | F27: MATERIALES DE ENSEÑANZA | G27: LIBRERÍA | I27: 26037 | J27: =+J26+H27-I27 -> 20742951
B28: 46091 | C28: 21 | D28: 2321-65-AG26 | E28: 771 | F28: MATERIALES DE ENSEÑANZA | G28: LIBRERÍA | I28: 1926217 | J28: =+J27+H28-I28 -> 18816734
B29: 46091 | C29: 23 | D29: 2321-93-AG26 | E29: 616 | F29: MATERIALES DE ENSEÑANZA | G29: LIBRERÍA | I29: 586016 | J29: =+J28+H29-I29 -> 18230718
B30: 46099 | E30: 293 | F30: INTERNET | G30: INTERNET | I30: 487783 | J30: =+J29+H30-I30 -> 17742935
B31: 46107 | C31: 29 | D31: 2321-154-TD26 | E31: 1100 | F31: PLATAFORMA | G31: PLATAFORMA 7.680.000 / 1 CUOTAS | I31: 4388572 | J31: =+J30+H31-I31 -> 13354363
J32: =+J31+H32-I32 -> 13354363
J33: =+J32+H33-I33 -> 13354363
B34: ABRIL
F35: SUBVENCION | G35: SUBVENCION | H35: =SUBVENCION!I7+SUBVENCION!J7 -> 35182209 | J35: =+J33+H35-I35 -> 48536572 | K35: ABRIL | L35: INGRESOS | M35: 10% ADM | N35: RR.HH. | O35: BNS Y SERV | P35: SALDO
